Traceback (most recent call last):
  File "/home/daineto/CostFOND/planner/pyperplan/pyperplan/task.py", line 63, in apply
    return (state - self.del_effects) | self.add_effects
MemoryError

During handling of the above exception, another exception occurred:

MemoryError

During handling of the above exception, another exception occurred:

MemoryError

During handling of the above exception, another exception occurred:

MemoryError

During handling of the above exception, another exception occurred:

MemoryError

During handling of the above exception, another exception occurred:

MemoryError

During handling of the above exception, another exception occurred:

MemoryError

During handling of the above exception, another exception occurred:

MemoryError
real 325.18
user 314.79
sys 12.84
