MemoryError

During handling of the above exception, another exception occurred:

MemoryError

During handling of the above exception, another exception occurred:

Traceback (most recent call last):
  File "/home/daineto/CostFOND/planner/planner.py", line 59, in get_f_value
    f_worst = max([policy.get_worst_g(state) for state in Out], default=math.inf)
MemoryError

During handling of the above exception, another exception occurred:

MemoryError

During handling of the above exception, another exception occurred:

MemoryError

During handling of the above exception, another exception occurred:

MemoryError
real 251.96
user 244.10
sys 11.21
