MemoryError

During handling of the above exception, another exception occurred:

Traceback (most recent call last):
  File "/home/daineto/CostFOND/planner/planner.py", line 205, in update_g_values
    update_g_brute(policy, task)
MemoryError

During handling of the above exception, another exception occurred:

MemoryError

During handling of the above exception, another exception occurred:

MemoryError

During handling of the above exception, another exception occurred:

MemoryError

During handling of the above exception, another exception occurred:

MemoryError
real 255.57
user 247.57
sys 11.17
