MemoryError

During handling of the above exception, another exception occurred:

Traceback (most recent call last):
  File "/home/daineto/CostFOND/planner/planner.py", line 622, in main
    solution = boand_star(domain_file, problem_file, solution_folder, use_metric=metric, use_cp_heuristic=heuristic, use_best_case_heuristic=best_heuristic, use_worst_case_heuristic=worst_heuristic, use_size_heuristic=size_heuristic, use_selector=selector)
  File "/home/daineto/CostFOND/planner/planner.py", line 527, in boand_star
    new_policy = extend_policy(current_policy, state, nondet_action, nondet_to_det_action[nondet_action], nondet_action_to_successors[nondet_action], task)
  File "/home/daineto/CostFOND/planner/planner.py", line 267, in extend_policy
    new_policy = current_policy.copy()
MemoryError

During handling of the above exception, another exception occurred:

MemoryError
real 306.00
user 296.79
sys 11.71
